Workbook

Sheet README
A1: CARD FINDER
A2: Version 10 (October 2026)
A4: PURPOSE
A5: Find the cards you need in a game shop's binders without flipping through every one. Shops sort singles binders by set, and a card can be printed in a dozen sets. Card Finder looks up every set each card was printed in, matches them to the shop's binders, and tells you which binders to pull and which cards to look for in each.
A7: QUICK START
A8: 1. Export a decklist from Moxfield, Archidekt or EDHREC as plain text (lines like "1 Sol Ring").
A9: 2. Paste it into column C of a green list tab, starting at C2.
A10: 3. Card Finder > Fetch card data (this tab). Counts move to column B, names get corrected, and the row fills in from Scryfall: every set the card was printed in, the price in each set, colors and an image link.
A11: 4. Mark what you already own in column A (see STATUS).
A12: 5. Open Binder Plan or Shop. Binders are built automatically from your needed cards.
A14: STATUS (column A of each list tab)
A15: TRUE: You own it. Not needed.
... A67: The script checks this tab's version line on open and warns if the sheet and script versions don't match.

Sheet Use at Shop
A1: Shop: one binder at a time
A2: Shows the top binder from Binder Plan, or pick one. Tick Found? for each card you find (it's marked TRUE on its list). Tick Done / not here when you've finished the binder or the shop doesn't have it, and the next one comes up.
A3: Pick a binder: | B3: Foundations | D3: Done / not here: | E3: FALSE
A4: Showing: | B4: =IF(B3<>"",B3,Binders!$B$6) -> Foundations | C4: =COUNT(H6:H205)&" cards" -> 16 cards | D4: Show images: | E4: TRUE
A5: Found? | B5: Card | C5: Color | D5: Set in this binder | E5: Price | F5: List | G5: Image | H5: key
A6: FALSE | B6: {=IF($H6="","",INDEX('Binder Data'!$A:$A,$H6))} -> Sephara, Sky's Blade | C6: {=IF($H6="","",INDEX('Binder Data'!$L:$L,$H6))} -> White | D6: {=IF($H6="","",INDEX('Binder Data'!$I:$I,$H6))} -> The List | E6: {=IF($H6="","",INDEX('Binder Data'!$F:$F,$H6))} -> 6.61 | F6: {=IF($H6="","",INDEX('Binder Data'!$Q:$Q,$H6))} -> Deck 1 | G6: {=IF(OR($H6="",$E$4<>TRUE()),"",IFERROR(IMAGE(INDEX('Binder Data'!$O:$O,$H6)),""))} | H6: =IFERROR(MATCH(SMALL('Binder Data'!$M$2:$M$6251,1),'Binder Data'!$M$2:$M$6251,0)+1,"") -> 304
A7: FALSE | B7: {=IF($H7="","",INDEX('Binder Data'!$A:$A,$H7))} -> Blasphemous Act | C7: {=IF($H7="","",INDEX('Binder Data'!$L:$L,$H7))} -> Red | D7: {=IF($H7="","",INDEX('Binder Data'!$I:$I,$H7))} -> The List | E7: {=IF($H7="","",INDEX('Binder Data'!$F:$F,$H7))} -> 1.22 | F7: {=IF($H7="","",INDEX('Binder Data'!$Q:$Q,$H7))} -> Deck 1 | G7: {=IF(OR($H7="",$E$4<>TRUE()),"",IFERROR(IMAGE(INDEX('Binder Data'!$O:$O,$H7)),""))} | H7: =IFERROR(MATCH(SMALL('Binder Data'!$M$2:$M$6251,2),'Binder Data'!$M$2:$M$6251,0)+1,"") -> 256
A8: FALSE | B8: {=IF($H8="","",INDEX('Binder Data'!$A:$A,$H8))} -> Dark-Dweller Oracle | C8: {=IF($H8="","",INDEX('Binder Data'!$L:$L,$H8))} -> Red | D8: {=IF($H8="","",INDEX('Binder Data'!$I:$I,$H8))} -> The List | E8: {=IF($H8="","",INDEX('Binder Data'!$F:$F,$H8))} -> 0.22 | F8: {=IF($H8="","",INDEX('Binder Data'!$Q:$Q,$H8))} -> Deck 1 | G8: {=IF(OR($H8="",$E$4<>TRUE()),"",IFERROR(IMAGE(INDEX('Binder Data'!$O:$O,$H8)),""))} | H8: =IFERROR(MATCH(SMALL('Binder Data'!$M$2:$M$6251,3),'Binder Data'!$M$2:$M$6251,0)+1,"") -> 269
A9: FALSE | B9: {=IF($H9="","",INDEX('Binder Data'!$A:$A,$H9))} -> Loyal Apprentice | C9: {=IF($H9="","",INDEX('Binder Data'!$L:$L,$H9))} -> Red | D9: {=IF($H9="","",INDEX('Binder Data'!$I:$I,$H9))} -> The List | E9: {=IF($H9="","",INDEX('Binder Data'!$F:$F,$H9))} -> 0.37 | F9: {=IF($H9="","",INDEX('Binder Data'!$Q:$Q,$H9))} -> Deck 1 | G9: {=IF(OR($H9="",$E$4<>TRUE()),"",IFERROR(IMAGE(INDEX('Binder Data'!$O:$O,$H9)),""))} | H9: =IFERROR(MATCH(SMALL('Binder Data'!$M$2:$M$6251,4),'Binder Data'!$M$2:$M$6251,0)+1,"") -> 285
A10: FALSE | B10: {=IF($H10="","",INDEX('Binder Data'!$A:$A,$H10))} -> Reckless Fireweaver | C10: {=IF($H10="","",INDEX('Binder Data'!$L:$L,$H10))} -> Red | D10: {=IF($H10="","",INDEX('Binder Data'!$I:$I,$H10))} -> The List | E10: {=IF($H10="","",INDEX('Binder Data'!$F:$F,$H10))} -> 0.92 | F10: {=IF($H10="","",INDEX('Binder Data'!$Q:$Q,$H10))} -> Deck 1 | G10: {=IF(OR($H10="",$E$4<>TRUE()),"",IFERROR(IMAGE(INDEX('Binder Data'!$O:$O,$H10)),""))} | H10: =IFERROR(MATCH(SMALL('Binder Data'!$M$2:$M$6251,5),'Binder Data'!$M$2:$M$6251,0)+1,"") -> 298
A11: FALSE | B11: {=IF($H11="","",INDEX('Binder Data'!$A:$A,$H11))} -> Anim Pakal, Thousandth Moon | C11: {=IF($H11="","",INDEX('Binder Data'!$L:$L,$H11))} -> Multicolor | D11: {=IF($H11="","",INDEX('Binder Data'!$I:$I,$H11))} -> The List | E11: {=IF($H11="","",INDEX('Binder Data'!$F:$F,$H11))} -> 0 | F11: {=IF($H11="","",INDEX('Binder Data'!$Q:$Q,$H11))} -> Deck 1 | G11: {=IF(OR($H11="",$E$4<>TRUE()),"",IFERROR(IMAGE(INDEX('Binder Data'!$O:$O,$H11)),""))} | H11: =IFERROR(MATCH(SMALL('Binder Data'!$M$2:$M$6251,6),'Binder Data'!$M$2:$M$6251,0)+1,"") -> 252
A12: FALSE | B12: {=IF($H12="","",INDEX('Binder Data'!$A:$A,$H12))} -> Arabella, Abandoned Doll | C12: {=IF($H12="","",INDEX('Binder Data'!$L:$L,$H12))} -> Multicolor | D12: {=IF($H12="","",INDEX('Binder Data'!$I:$I,$H12))} -> The List | E12: {=IF($H12="","",INDEX('Binder Data'!$F:$F,$H12))} -> 0.77 | F12: {=IF($H12="","",INDEX('Binder Data'!$Q:$Q,$H12))} -> Deck 1 | G12: {=IF(OR($H12="",$E$4<>TRUE()),"",IFERROR(IMAGE(INDEX('Binder Data'!$O:$O,$H12)),""))} | H12: =IFERROR(MATCH(SMALL('Binder Data'!$M$2:$M$6251,7),'Binder Data'!$M$2:$M$6251,0)+1,"") -> 253
A13: FALSE | B13: {=IF($H13="","",INDEX('Binder Data'!$A:$A,$H13))} -> Chief of the Foundry | C13: {=IF($H13="","",INDEX('Binder Data'!$L:$L,$H13))} -> Colorless | D13: {=IF($H13="","",INDEX('Binder Data'!$I:$I,$H13))} -> Foundations Jumpstart | E13: {=IF($H13="","",INDEX('Binder Data'!$F:$F,$H13))} -> 0.33 | F13: {=IF($H13="","",INDEX('Binder Data'!$Q:$Q,$H13))} -> Deck 1 | G13: {=IF(OR($H13="",$E$4<>TRUE()),"",IFERROR(IMAGE(INDEX('Binder Data'!$O:$O,$H13)),""))} | H13: =IFERROR(MATCH(SMALL('Binder Data'!$M$2:$M$6251,8),'Binder Data'!$M$2:$M$6251,0)+1,"") -> 263
A14: FALSE | B14: {=IF($H14="","",INDEX('Binder Data'!$A:$A,$H14))} -> Ornithopter of Paradise | C14: {=IF($H14="","",INDEX('Binder Data'!$L:$L,$H14))} -> Colorless | D14: {=IF($H14="","",INDEX('Binder Data'!$I:$I,$H14))} -> Foundations Jumpstart | E14: {=IF($H14="","",INDEX('Binder Data'!$F:$F,$H14))} -> 0.51 | F14: {=IF($H14="","",INDEX('Binder Data'!$Q:$Q,$H14))} -> Deck 1 | G14: {=IF(OR($H14="",$E$4<>TRUE()),"",IFERROR(IMAGE(INDEX('Binder Data'!$O:$O,$H14)),""))} | H14: =IFERROR(MATCH(SMALL('Binder Data'!$M$2:$M$6251,9),'Binder Data'!$M$2:$M$6251,0)+1,"") -> 290
A15: FALSE | B15: {=IF($H15="","",INDEX('Binder Data'!$A:$A,$H15))} -> Castle Embereth | C15: {=IF($H15="","",INDEX('Binder Data'!$L:$L,$H15))} -> Land | D15: {=IF($H15="","",INDEX('Binder Data'!$I:$I,$H15))} -> The List | E15: {=IF($H15="","",INDEX('Binder Data'!$F:$F,$H15))} -> 0.36 | F15: {=IF($H15="","",INDEX('Binder Data'!$Q:$Q,$H15))} -> Deck 1 | G15: {=IF(OR($H15="",$E$4<>TRUE()),"",IFERROR(IMAGE(INDEX('Binder Data'!$O:$O,$H15)),""))} | H15: =IFERROR(MATCH(SMALL('Binder Data'!$M$2:$M$6251,10),'Binder Data'!$M$2:$M$6251,0)+1,"") -> 260
A16: FALSE | B16: {=IF($H16="","",INDEX('Binder Data'!$A:$A,$H16))} -> Clifftop Retreat | C16: {=IF($H16="","",INDEX('Binder Data'!$L:$L,$H16))} -> Land | D16: {=IF($H16="","",INDEX('Binder Data'!$I:$I,$H16))} -> The List | E16: {=IF($H16="","",INDEX('Binder Data'!$F:$F,$H16))} -> 0.76 | F16: {=IF($H16="","",INDEX('Binder Data'!$Q:$Q,$H16))} -> Deck 1 | G16: {=IF(OR($H16="",$E$4<>TRUE()),"",IFERROR(IMAGE(INDEX('Binder Data'!$O:$O,$H16)),""))} | H16: =IFERROR(MATCH(SMALL('Binder Data'!$M$2:$M$6251,11),'Binder Data'!$M$2:$M$6251,0)+1,"") -> 264
A17: FALSE | B17: {=IF($H17="","",INDEX('Binder Data'!$A:$A,$H17))} -> Command Beacon | C17: {=IF($H17="","",INDEX('Binder Data'!$L:$L,$H17))} -> Land | D17: {=IF($H17="","",INDEX('Binder Data'!$I:$I,$H17))} -> The List | E17: {=IF($H17="","",INDEX('Binder Data'!$F:$F,$H17))} -> 10.61 | F17: {=IF($H17="","",INDEX('Binder Data'!$Q:$Q,$H17))} -> Deck 1 | G17: {=IF(OR($H17="",$E$4<>TRUE()),"",IFERROR(IMAGE(INDEX('Binder Data'!$O:$O,$H17)),""))} | H17: =IFERROR(MATCH(SMALL('Binder Data'!$M$2:$M$6251,12),'Binder Data'!$M$2:$M$6251,0)+1,"") -> 265
A18: FALSE | B18: {=IF($H18="","",INDEX('Binder Data'!$A:$A,$H18))} -> Command Tower | C18: {=IF($H18="","",INDEX('Binder Data'!$L:$L,$H18))} -> Land | D18: {=IF($H18="","",INDEX('Binder Data'!$I:$I,$H18))} -> The List | E18: {=IF($H18="","",INDEX('Binder Data'!$F:$F,$H18))} -> 0.36 | F18: {=IF($H18="","",INDEX('Binder Data'!$Q:$Q,$H18))} -> Deck 1 | G18: {=IF(OR($H18="",$E$4<>TRUE()),"",IFERROR(IMAGE(INDEX('Binder Data'!$O:$O,$H18)),""))} | H18: =IFERROR(MATCH(SMALL('Binder Data'!$M$2:$M$6251,13),'Binder Data'!$M$2:$M$6251,0)+1,"") -> 266
A19: FALSE | B19: {=IF($H19="","",INDEX('Binder Data'!$A:$A,$H19))} -> Demolition Field | C19: {=IF($H19="","",INDEX('Binder Data'!$L:$L,$H19))} -> Land | D19: {=IF($H19="","",INDEX('Binder Data'!$I:$I,$H19))} -> Foundations | E19: {=IF($H19="","",INDEX('Binder Data'!$F:$F,$H19))} -> 0.32 | F19: {=IF($H19="","",INDEX('Binder Data'!$Q:$Q,$H19))} -> Deck 1 | G19: {=IF(OR($H19="",$E$4<>TRUE()),"",IFERROR(IMAGE(INDEX('Binder Data'!$O:$O,$H19)),""))} | H19: =IFERROR(MATCH(SMALL('Binder Data'!$M$2:$M$6251,14),'Binder Data'!$M$2:$M$6251,0)+1,"") -> 270
A20: FALSE | B20: {=IF($H20="","",INDEX('Binder Data'!$A:$A,$H20))} -> Exotic Orchard | C20: {=IF($H20="","",INDEX('Binder Data'!$L:$L,$H20))} -> Land | D20: {=IF($H20="","",INDEX('Binder Data'!$I:$I,$H20))} -> The List | E20: {=IF($H20="","",INDEX('Binder Data'!$F:$F,$H20))} -> 0.28 | F20: {=IF($H20="","",INDEX('Binder Data'!$Q:$Q,$H20))} -> Deck 1 | G20: {=IF(OR($H20="",$E$4<>TRUE()),"",IFERROR(IMAGE(INDEX('Binder Data'!$O:$O,$H20)),""))} | H20: =IFERROR(MATCH(SMALL('Binder Data'!$M$2:$M$6251,15),'Binder Data'!$M$2:$M$6251,0)+1,"") -> 272
A21: FALSE | B21: {=IF($H21="","",INDEX('Binder Data'!$A:$A,$H21))} -> Fountainport | C21: {=IF($H21="","",INDEX('Binder Data'!$L:$L,$H21))} -> Land | D21: {=IF($H21="","",INDEX('Binder Data'!$I:$I,$H21))} -> The List | E21: {=IF($H21="","",INDEX('Binder Data'!$F:$F,$H21))} -> 3.45 | F21: {=IF($H21="","",INDEX('Binder Data'!$Q:$Q,$H21))} -> Deck 1 | G21: {=IF(OR($H21="",$E$4<>TRUE()),"",IFERROR(IMAGE(INDEX('Binder Data'!$O:$O,$H21)),""))} | H21: =IFERROR(MATCH(SMALL('Binder Data'!$M$2:$M$6251,16),'Binder Data'!$M$2:$M$6251,0)+1,"") -> 273
A22: FALSE | B22: {=IF($H22="","",INDEX('Binder Data'!$A:$A,$H22))} | C22: {=IF($H22="","",INDEX('Binder Data'!$L:$L,$H22))} | D22: {=IF($H22="","",INDEX('Binder Data'!$I:$I,$H22))} | E22: {=IF($H22="","",INDEX('Binder Data'!$F:$F,$H22))} | F22: {=IF($H22="","",INDEX('Binder Data'!$Q:$Q,$H22))} | G22: {=IF(OR($H22="",$E$4<>TRUE()),"",IFERROR(IMAGE(INDEX('Binder Data'!$O:$O,$H22)),""))} | H22: =IFERROR(MATCH(SMALL('Binder Data'!$M$2:$M$6251,17),'Binder Data'!$M$2:$M$6251,0)+1,"")
A23: FALSE | B23: {=IF($H23="","",INDEX('Binder Data'!$A:$A,$H23))} | C23: {=IF($H23="","",INDEX('Binder Data'!$L:$L,$H23))} | D23: {=IF($H23="","",INDEX('Binder Data'!$I:$I,$H23))} | E23: {=IF($H23="","",INDEX('Binder Data'!$F:$F,$H23))} | F23: {=IF($H23="","",INDEX('Binder Data'!$Q:$Q,$H23))} | G23: {=IF(OR($H23="",$E$4<>TRUE()),"",IFERROR(IMAGE(INDEX('Binder Data'!$O:$O,$H23)),""))} | H23: =IFERROR(MATCH(SMALL('Binder Data'!$M$2:$M$6251,18),'Binder Data'!$M$2:$M$6251,0)+1,"")
A24: FALSE | B24: {=IF($H24="","",INDEX('Binder Data'!$A:$A,$H24))} | C24: {=IF($H24="","",INDEX('Binder Data'!$L:$L,$H24))} | D24: {=IF($H24="","",INDEX('Binder Data'!$I:$I,$H24))} | E24: {=IF($H24="","",INDEX('Binder Data'!$F:$F,$H24))} | F24: {=IF($H24="","",INDEX('Binder Data'!$Q:$Q,$H24))} | G24: {=IF(OR($H24="",$E$4<>TRUE()),"",IFERROR(IMAGE(INDEX('Binder Data'!$O:$O,$H24)),""))} | H24: =IFERROR(MATCH(SMALL('Binder Data'!$M$2:$M$6251,19),'Binder Data'!$M$2:$M$6251,0)+1,"")
A25: FALSE | B25: {=IF($H25="","",INDEX('Binder Data'!$A:$A,$H25))} | C25: {=IF($H25="","",INDEX('Binder Data'!$L:$L,$H25))} | D25: {=IF($H25="","",INDEX('Binder Data'!$I:$I,$H25))} | E25: {=IF($H25="","",INDEX('Binder Data'!$F:$F,$H25))} | F25: {=IF($H25="","",INDEX('Binder Data'!$Q:$Q,$H25))} | G25: {=IF(OR($H25="",$E$4<>TRUE()),"",IFERROR(IMAGE(INDEX('Binder Data'!$O:$O,$H25)),""))} | H25: =IFERROR(MATCH(SMALL('Binder Data'!$M$2:$M$6251,20),'Binder Data'!$M$2:$M$6251,0)+1,"")
A26: FALSE | B26: {=IF($H26="","",INDEX('Binder Data'!$A:$A,$H26))} | C26: {=IF($H26="","",INDEX('Binder Data'!$L:$L,$H26))} | D26: {=IF($H26="","",INDEX('Binder Data'!$I:$I,$H26))} | E26: {=IF($H26="","",INDEX('Binder Data'!$F:$F,$H26))} | F26: {=IF($H26="","",INDEX('Binder Data'!$Q:$Q,$H26))} | G26: {=IF(OR($H26="",$E$4<>TRUE()),"",IFERROR(IMAGE(INDEX('Binder Data'!$O:$O,$H26)),""))} | H26: =IFERROR(MATCH(SMALL('Binder Data'!$M$2:$M$6251,21),'Binder Data'!$M$2:$M$6251,0)+1,"")
A27: FALSE | B27: {=IF($H27="","",INDEX('Binder Data'!$A:$A,$H27))} | C27: {=IF($H27="","",INDEX('Binder Data'!$L:$L,$H27))} | D27: {=IF($H27="","",INDEX('Binder Data'!$I:$I,$H27))} | E27: {=IF($H27="","",INDEX('Binder Data'!$F:$F,$H27))} | F27: {=IF($H27="","",INDEX('Binder Data'!$Q:$Q,$H27))} | G27: {=IF(OR($H27="",$E$4<>TRUE()),"",IFERROR(IMAGE(INDEX('Binder Data'!$O:$O,$H27)),""))} | H27: =IFERROR(MATCH(SMALL('Binder Data'!$M$2:$M$6251,22),'Binder Data'!$M$2:$M$6251,0)+1,"")
A28: FALSE | B28: {=IF($H28="","",INDEX('Binder Data'!$A:$A,$H28))} | C28: {=IF($H28="","",INDEX('Binder Data'!$L:$L,$H28))} | D28: {=IF($H28="","",INDEX('Binder Data'!$I:$I,$H28))} | E28: {=IF($H28="","",INDEX('Binder Data'!$F:$F,$H28))} | F28: {=IF($H28="","",INDEX('Binder Data'!$Q:$Q,$H28))} | G28: {=IF(OR($H28="",$E$4<>TRUE()),"",IFERROR(IMAGE(INDEX('Binder Data'!$O:$O,$H28)),""))} | H28: =IFERROR(MATCH(SMALL('Binder Data'!$M$2:$M$6251,23),'Binder Data'!$M$2:$M$6251,0)+1,"")
A29: FALSE | B29: {=IF($H29="","",INDEX('Binder Data'!$A:$A,$H29))} | C29: {=IF($H29="","",INDEX('Binder Data'!$L:$L,$H29))} | D29: {=IF($H29="","",INDEX('Binder Data'!$I:$I,$H29))} | E29: {=IF($H29="","",INDEX('Binder Data'!$F:$F,$H29))} | F29: {=IF($H29="","",INDEX('Binder Data'!$Q:$Q,$H29))} | G29: {=IF(OR($H29="",$E$4<>TRUE()),"",IFERROR(IMAGE(INDEX('Binder Data'!$O:$O,$H29)),""))} | H29: =IFERROR(MATCH(SMALL('Binder Data'!$M$2:$M$6251,24),'Binder Data'!$M$2:$M$6251,0)+1,"")
A30: FALSE | B30: {=IF($H30="","",INDEX('Binder Data'!$A:$A,$H30))} | C30: {=IF($H30="","",INDEX('Binder Data'!$L:$L,$H30))} | D30: {=IF($H30="","",INDEX('Binder Data'!$I:$I,$H30))} | E30: {=IF($H30="","",INDEX('Binder Data'!$F:$F,$H30))} | F30: {=IF($H30="","",INDEX('Binder Data'!$Q:$Q,$H30))} | G30: {=IF(OR($H30="",$E$4<>TRUE()),"",IFERROR(IMAGE(INDEX('Binder Data'!$O:$O,$H30)),""))} | H30: =IFERROR(MATCH(SMALL('Binder Data'!$M$2:$M$6251,25),'Binder Data'!$M$2:$M$6251,0)+1,"")
A31: FALSE | B31: {=IF($H31="","",INDEX('Binder Data'!$A:$A,$H31))} | C31: {=IF($H31="","",INDEX('Binder Data'!$L:$L,$H31))} | D31: {=IF($H31="","",INDEX('Binder Data'!$I:$I,$H31))} | E31: {=IF($H31="","",INDEX('Binder Data'!$F:$F,$H31))} | F31: {=IF($H31="","",INDEX('Binder Data'!$Q:$Q,$H31))} | G31: {=IF(OR($H31="",$E$4<>TRUE()),"",IFERROR(IMAGE(INDEX('Binder Data'!$O:$O,$H31)),""))} | H31: =IFERROR(MATCH(SMALL('Binder Data'!$M$2:$M$6251,26),'Binder Data'!$M$2:$M$6251,0)+1,"")
A32: FALSE | B32: {=IF($H32="","",INDEX('Binder Data'!$A:$A,$H32))} | C32: {=IF($H32="","",INDEX('Binder Data'!$L:$L,$H32))} | D32: {=IF($H32="","",INDEX('Binder Data'!$I:$I,$H32))} | E32: {=IF($H32="","",INDEX('Binder Data'!$F:$F,$H32))} | F32: {=IF($H32="","",INDEX('Binder Data'!$Q:$Q,$H32))} | G32: {=IF(OR($H32="",$E$4<>TRUE()),"",IFERROR(IMAGE(INDEX('Binder Data'!$O:$O,$H32)),""))} | H32: =IFERROR(MATCH(SMALL('Binder Data'!$M$2:$M$6251,27),'Binder Data'!$M$2:$M$6251,0)+1,"")
A33: FALSE | B33: {=IF($H33="","",INDEX('Binder Data'!$A:$A,$H33))} | C33: {=IF($H33="","",INDEX('Binder Data'!$L:$L,$H33))} | D33: {=IF($H33="","",INDEX('Binder Data'!$I:$I,$H33))} | E33: {=IF($H33="","",INDEX('Binder Data'!$F:$F,$H33))} | F33: {=IF($H33="","",INDEX('Binder Data'!$Q:$Q,$H33))} | G33: {=IF(OR($H33="",$E$4<>TRUE()),"",IFERROR(IMAGE(INDEX('Binder Data'!$O:$O,$H33)),""))} | H33: =IFERROR(MATCH(SMALL('Binder Data'!$M$2:$M$6251,28),'Binder Data'!$M$2:$M$6251,0)+1,"")
A34: FALSE | B34: {=IF($H34="","",INDEX('Binder Data'!$A:$A,$H34))} | C34: {=IF($H34="","",INDEX('Binder Data'!$L:$L,$H34))} | D34: {=IF($H34="","",INDEX('Binder Data'!$I:$I,$H34))} | E34: {=IF($H34="","",INDEX('Binder Data'!$F:$F,$H34))} | F34: {=IF($H34="","",INDEX('Binder Data'!$Q:$Q,$H34))} | G34: {=IF(OR($H34="",$E$4<>TRUE()),"",IFERROR(IMAGE(INDEX('Binder Data'!$O:$O,$H34)),""))} | H34: =IFERROR(MATCH(SMALL('Binder Data'!$M$2:$M$6251,29),'Binder Data'!$M$2:$M$6251,0)+1,"")
A35: FALSE | B35: {=IF($H35="","",INDEX('Binder Data'!$A:$A,$H35))} | C35: {=IF($H35="","",INDEX('Binder Data'!$L:$L,$H35))} | D35: {=IF($H35="","",INDEX('Binder Data'!$I:$I,$H35))} | E35: {=IF($H35="","",INDEX('Binder Data'!$F:$F,$H35))} | F35: {=IF($H35="","",INDEX('Binder Data'!$Q:$Q,$H35))} | G35: {=IF(OR($H35="",$E$4<>TRUE()),"",IFERROR(IMAGE(INDEX('Binder Data'!$O:$O,$H35)),""))} | H35: =IFERROR(MATCH(SMALL('Binder Data'!$M$2:$M$6251,30),'Binder Data'!$M$2:$M$6251,0)+1,"")
A36: FALSE | B36: {=IF($H36="","",INDEX('Binder Data'!$A:$A,$H36))} | C36: {=IF($H36="","",INDEX('Binder Data'!$L:$L,$H36))} | D36: {=IF($H36="","",INDEX('Binder Data'!$I:$I,$H36))} | E36: {=IF($H36="","",INDEX('Binder Data'!$F:$F,$H36))} | F36: {=IF($H36="","",INDEX('Binder Data'!$Q:$Q,$H36))} | G36: {=IF(OR($H36="",$E$4<>TRUE()),"",IFERROR(IMAGE(INDEX('Binder Data'!$O:$O,$H36)),""))} | H36: =IFERROR(MATCH(SMALL('Binder Data'!$M$2:$M$6251,31),'Binder Data'!$M$2:$M$6251,0)+1,"")
A37: FALSE | B37: {=IF($H37="","",INDEX('Binder Data'!$A:$A,$H37))} | C37: {=IF($H37="","",INDEX('Binder Data'!$L:$L,$H37))} | D37: {=IF($H37="","",INDEX('Binder Data'!$I:$I,$H37))} | E37: {=IF($H37="","",INDEX('Binder Data'!$F:$F,$H37))} | F37: {=IF($H37="","",INDEX('Binder Data'!$Q:$Q,$H37))} | G37: {=IF(OR($H37="",$E$4<>TRUE()),"",IFERROR(IMAGE(INDEX('Binder Data'!$O:$O,$H37)),""))} | H37: =IFERROR(MATCH(SMALL('Binder Data'!$M$2:$M$6251,32),'Binder Data'!$M$2:$M$6251,0)+1,"")
A38: FALSE | B38: {=IF($H38="","",INDEX('Binder Data'!$A:$A,$H38))} | C38: {=IF($H38="","",INDEX('Binder Data'!$L:$L,$H38))} | D38: {=IF($H38="","",INDEX('Binder Data'!$I:$I,$H38))} | E38: {=IF($H38="","",INDEX('Binder Data'!$F:$F,$H38))} | F38: {=IF($H38="","",INDEX('Binder Data'!$Q:$Q,$H38))} | G38: {=IF(OR($H38="",$E$4<>TRUE()),"",IFERROR(IMAGE(INDEX('Binder Data'!$O:$O,$H38)),""))} | H38: =IFERROR(MATCH(SMALL('Binder Data'!$M$2:$M$6251,33),'Binder Data'!$M$2:$M$6251,0)+1,"")
A39: FALSE | B39: {=IF($H39="","",INDEX('Binder Data'!$A:$A,$H39))} | C39: {=IF($H39="","",INDEX('Binder Data'!$L:$L,$H39))} | D39: {=IF($H39="","",INDEX('Binder Data'!$I:$I,$H39))} | E39: {=IF($H39="","",INDEX('Binder Data'!$F:$F,$H39))} | F39: {=IF($H39="","",INDEX('Binder Data'!$Q:$Q,$H39))} | G39: {=IF(OR($H39="",$E$4<>TRUE()),"",IFERROR(IMAGE(INDEX('Binder Data'!$O:$O,$H39)),""))} | H39: =IFERROR(MATCH(SMALL('Binder Data'!$M$2:$M$6251,34),'Binder Data'!$M$2:$M$6251,0)+1,"")
A40: FALSE | B40: {=IF($H40="","",INDEX('Binder Data'!$A:$A,$H40))} | C40: {=IF($H40="","",INDEX('Binder Data'!$L:$L,$H40))} | D40: {=IF($H40="","",INDEX('Binder Data'!$I:$I,$H40))} | E40: {=IF($H40="","",INDEX('Binder Data'!$F:$F,$H40))} | F40: {=IF($H40="","",INDEX('Binder Data'!$Q:$Q,$H40))} | G40: {=IF(OR($H40="",$E$4<>TRUE()),"",IFERROR(IMAGE(INDEX('Binder Data'!$O:$O,$H40)),""))} | H40: =IFERROR(MATCH(SMALL('Binder Data'!$M$2:$M$6251,35),'Binder Data'!$M$2:$M$6251,0)+1,"")
...

Sheet Binders
A1: Card finder: binder pull plan
A2: Binders are built automatically from your needed cards, most cards first. Tick Searched / No binder when you've checked a binder or the shop doesn't have it: it drops off and its cards move to their next binder. Ticked one by mistake? Pick it in Bring back a binder (B4). Lists to search (right) chooses which lists count.
A3: Worth a binder pull if it holds at least this many cards (D3) or this much value (E3): | D3: 2 | E3: 1 | F3: Reset all: | G3: FALSE
A4: Bring back a binder:
A5: Pull # | B5: Binder / set | C5: Cards to look for here | D5: Cards left to find | E5: Value of cards left here | F5: Worth the pull? | G5: Searched / No binder | I5: List | J5: Search it? | K5: Cards still needed
A6: =IF(B6="","",1) -> 1 | B6: {=IFERROR(INDEX('Binder Setup'!$B$2:$B$401,MATCH(1,'Binder Setup'!$G$2:$G$401,0)),"")} -> Foundations | C6: {=IF(B6="","",TEXTJOIN(", ",TRUE(),IF(('Binder Data'!$B$2:$B$6251=B6)*('Binder Data'!$E$2:$E$6251="Y"),'Binder Data'!$G$2:$G$6251,"")))} -> Anim Pakal, Thousandth Moon [Deck 1], Arabella, Abandoned Doll [Deck 1], Blasphemous Act [Deck 1], Castle Embereth [Deck 1], Chief of the Foundry [Deck 1], Clifftop Retreat [Deck 1], Command Beacon [Deck 1], Command Tower [Deck 1], Dark-Dweller Oracle [Deck 1], Demolition Field [Deck 1], Exotic Orchard [Deck 1], Fountainport [Deck 1], Loyal Apprentice [Deck 1], Ornithopter of Paradise [Deck 1], Reckless Fireweaver [Deck 1], Sephara, Sky's Blade [Deck 1] | D6: {=IF(B6="","",INDEX('Binder Setup'!$D$2:$D$401,MATCH(1,'Binder Setup'!$G$2:$G$401,0)))} -> 16 | E6: {=IF(B6="","",INDEX('Binder Setup'!$E$2:$E$401,MATCH(1,'Binder Setup'!$G$2:$G$401,0)))} -> 27.09 | F6: =IF(B6="","",IF(OR(D6>=$D$3,E6>=$E$3),"Pull","Skip: buy elsewhere")) -> Pull | G6: FALSE | I6: Wishlist | J6: TRUE | K6: =IF(I6="","",COUNTIFS('Binder Data'!$Q$2:$Q$6251,I6,'Binder Data'!$D$2:$D$6251,"Needed")) -> 0
A7: =IF(B7="","",2) -> 2 | B7: {=IFERROR(INDEX('Binder Setup'!$B$2:$B$401,MATCH(2,'Binder Setup'!$G$2:$G$401,0)),"")} -> Commander Box | C7: {=IF(B7="","",TEXTJOIN(", ",TRUE(),IF(('Binder Data'!$B$2:$B$6251=B7)*('Binder Data'!$E$2:$E$6251="Y"),'Binder Data'!$G$2:$G$6251,"")))} -> Rose, Cutthroat Raider [Deck 1], Scavenger Grounds [Deck 1], Sentinel Sarah Lyons [Deck 1], Spire of Industry [Deck 1], Steel Overseer [Deck 1], Sunscorched Divide [Deck 1], Talisman of Conviction [Deck 1], Wild Wasteland [Deck 1], Windbrisk Heights [Deck 1] | D7: {=IF(B7="","",INDEX('Binder Setup'!$D$2:$D$401,MATCH(2,'Binder Setup'!$G$2:$G$401,0)))} -> 9 | E7: {=IF(B7="","",INDEX('Binder Setup'!$E$2:$E$401,MATCH(2,'Binder Setup'!$G$2:$G$401,0)))} -> 4.42 | F7: =IF(B7="","",IF(OR(D7>=$D$3,E7>=$E$3),"Pull","Skip: buy elsewhere")) -> Pull | G7: FALSE | I7: Deck 1 | J7: TRUE | K7: =IF(I7="","",COUNTIFS('Binder Data'!$Q$2:$Q$6251,I7,'Binder Data'!$D$2:$D$6251,"Needed")) -> 68
A8: =IF(B8="","",3) -> 3 | B8: {=IFERROR(INDEX('Binder Setup'!$B$2:$B$401,MATCH(3,'Binder Setup'!$G$2:$G$401,0)),"")} -> Secret Lair Drop | C8: {=IF(B8="","",TEXTJOIN(", ",TRUE(),IF(('Binder Data'!$B$2:$B$6251=B8)*('Binder Data'!$E$2:$E$6251="Y"),'Binder Data'!$G$2:$G$6251,"")))} -> Battlefield Forge [Deck 1], Boros Signet [Deck 1], Chandra, Fire Artisan [Deck 1], Hex Magic [Deck 1], Patchwork Banner [Deck 1], Professional Face-Breaker [Deck 1] | D8: {=IF(B8="","",INDEX('Binder Setup'!$D$2:$D$401,MATCH(3,'Binder Setup'!$G$2:$G$401,0)))} -> 6 | E8: {=IF(B8="","",INDEX('Binder Setup'!$E$2:$E$401,MATCH(3,'Binder Setup'!$G$2:$G$401,0)))} -> 116.87 | F8: =IF(B8="","",IF(OR(D8>=$D$3,E8>=$E$3),"Pull","Skip: buy elsewhere")) -> Pull | G8: FALSE | I8: Deck 2 | J8: TRUE | K8: =IF(I8="","",COUNTIFS('Binder Data'!$Q$2:$Q$6251,I8,'Binder Data'!$D$2:$D$6251,"Needed")) -> 0
A9: =IF(B9="","",4) -> 4 | B9: {=IFERROR(INDEX('Binder Setup'!$B$2:$B$401,MATCH(4,'Binder Setup'!$G$2:$G$401,0)),"")} -> Commander Masters | C9: {=IF(B9="","",TEXTJOIN(", ",TRUE(),IF(('Binder Data'!$B$2:$B$6251=B9)*('Binder Data'!$E$2:$E$6251="Y"),'Binder Data'!$G$2:$G$6251,"")))} -> Chandra, Torch of Defiance [Deck 1], Furycalm Snarl [Deck 1], Losheel, Clockwork Scholar [Deck 1], Rugged Prairie [Deck 1] | D9: {=IF(B9="","",INDEX('Binder Setup'!$D$2:$D$401,MATCH(4,'Binder Setup'!$G$2:$G$401,0)))} -> 4 | E9: {=IF(B9="","",INDEX('Binder Setup'!$E$2:$E$401,MATCH(4,'Binder Setup'!$G$2:$G$401,0)))} -> 6.97 | F9: =IF(B9="","",IF(OR(D9>=$D$3,E9>=$E$3),"Pull","Skip: buy elsewhere")) -> Pull | G9: FALSE | I9: Deck 3 | J9: TRUE | K9: =IF(I9="","",COUNTIFS('Binder Data'!$Q$2:$Q$6251,I9,'Binder Data'!$D$2:$D$6251,"Needed")) -> 0
A10: =IF(B10="","",5) -> 5 | B10: {=IFERROR(INDEX('Binder Setup'!$B$2:$B$401,MATCH(5,'Binder Setup'!$G$2:$G$401,0)),"")} -> Tarkir: Dragonstorm Commander | C10: {=IF(B10="","",TEXTJOIN(", ",TRUE(),IF(('Binder Data'!$B$2:$B$6251=B10)*('Binder Data'!$E$2:$E$6251="Y"),'Binder Data'!$G$2:$G$6251,"")))} -> Welcoming Vampire [Deck 1] | D10: {=IF(B10="","",INDEX('Binder Setup'!$D$2:$D$401,MATCH(5,'Binder Setup'!$G$2:$G$401,0)))} -> 1 | E10: {=IF(B10="","",INDEX('Binder Setup'!$E$2:$E$401,MATCH(5,'Binder Setup'!$G$2:$G$401,0)))} -> 3.22 | F10: =IF(B10="","",IF(OR(D10>=$D$3,E10>=$E$3),"Pull","Skip: buy elsewhere")) -> Pull | G10: FALSE | I10: Deck 4 | J10: TRUE | K10: =IF(I10="","",COUNTIFS('Binder Data'!$Q$2:$Q$6251,I10,'Binder Data'!$D$2:$D$6251,"Needed")) -> 0
A11: =IF(B11="","",6) -> 6 | B11: {=IFERROR(INDEX('Binder Setup'!$B$2:$B$401,MATCH(6,'Binder Setup'!$G$2:$G$401,0)),"")} -> Secrets of Strixhaven Commander | C11: {=IF(B11="","",TEXTJOIN(", ",TRUE(),IF(('Binder Data'!$B$2:$B$6251=B11)*('Binder Data'!$E$2:$E$6251="Y"),'Binder Data'!$G$2:$G$6251,"")))} -> Laelia, the Blade Reforged [Deck 1], Radiant Summit [Deck 1] | D11: {=IF(B11="","",INDEX('Binder Setup'!$D$2:$D$401,MATCH(6,'Binder Setup'!$G$2:$G$401,0)))} -> 2 | E11: {=IF(B11="","",INDEX('Binder Setup'!$E$2:$E$401,MATCH(6,'Binder Setup'!$G$2:$G$401,0)))} -> 0.77 | F11: =IF(B11="","",IF(OR(D11>=$D$3,E11>=$E$3),"Pull","Skip: buy elsewhere")) -> Pull | G11: FALSE | I11: Deck 5 | J11: TRUE | K11: =IF(I11="","",COUNTIFS('Binder Data'!$Q$2:$Q$6251,I11,'Binder Data'!$D$2:$D$6251,"Needed")) -> 0
A12: =IF(B12="","",7) -> 7 | B12: {=IFERROR(INDEX('Binder Setup'!$B$2:$B$401,MATCH(7,'Binder Setup'!$G$2:$G$401,0)),"")} -> Commander 2021 | C12: {=IF(B12="","",TEXTJOIN(", ",TRUE(),IF(('Binder Data'!$B$2:$B$6251=B12)*('Binder Data'!$E$2:$E$6251="Y"),'Binder Data'!$G$2:$G$6251,"")))} -> Jor Kadeen, the Prevailer [Deck 1], Pia Nalaar [Deck 1] | D12: {=IF(B12="","",INDEX('Binder Setup'!$D$2:$D$401,MATCH(7,'Binder Setup'!$G$2:$G$401,0)))} -> 2 | E12: {=IF(B12="","",INDEX('Binder Setup'!$E$2:$E$401,MATCH(7,'Binder Setup'!$G$2:$G$401,0)))} -> 0.6 | F12: =IF(B12="","",IF(OR(D12>=$D$3,E12>=$E$3),"Pull","Skip: buy elsewhere")) -> Pull | G12: FALSE | J12: FALSE | K12: =IF(I12="","",COUNTIFS('Binder Data'!$Q$2:$Q$6251,I12,'Binder Data'!$D$2:$D$6251,"Needed"))
A13: =IF(B13="","",8) -> 8 | B13: {=IFERROR(INDEX('Binder Setup'!$B$2:$B$401,MATCH(8,'Binder Setup'!$G$2:$G$401,0)),"")} -> Edge of Eternities Commander | C13: {=IF(B13="","",TEXTJOIN(", ",TRUE(),IF(('Binder Data'!$B$2:$B$6251=B13)*('Binder Data'!$E$2:$E$6251="Y"),'Binder Data'!$G$2:$G$6251,"")))} -> Long-Range Sensor [Deck 1] | D13: {=IF(B13="","",INDEX('Binder Setup'!$D$2:$D$401,MATCH(8,'Binder Setup'!$G$2:$G$401,0)))} -> 1 | E13: {=IF(B13="","",INDEX('Binder Setup'!$E$2:$E$401,MATCH(8,'Binder Setup'!$G$2:$G$401,0)))} -> 0.28 | F13: =IF(B13="","",IF(OR(D13>=$D$3,E13>=$E$3),"Pull","Skip: buy elsewhere")) -> Skip: buy elsewhere | G13: FALSE | J13: FALSE | K13: =IF(I13="","",COUNTIFS('Binder Data'!$Q$2:$Q$6251,I13,'Binder Data'!$D$2:$D$6251,"Needed"))
A14: =IF(B14="","",9) -> 9 | B14: {=IFERROR(INDEX('Binder Setup'!$B$2:$B$401,MATCH(9,'Binder Setup'!$G$2:$G$401,0)),"")} -> Phyrexia: All Will Be One Commander | C14: {=IF(B14="","",TEXTJOIN(", ",TRUE(),IF(('Binder Data'!$B$2:$B$6251=B14)*('Binder Data'!$E$2:$E$6251="Y"),'Binder Data'!$G$2:$G$6251,"")))} -> Neyali, Suns' Vanguard [Deck 1] | D14: {=IF(B14="","",INDEX('Binder Setup'!$D$2:$D$401,MATCH(9,'Binder Setup'!$G$2:$G$401,0)))} -> 1 | E14: {=IF(B14="","",INDEX('Binder Setup'!$E$2:$E$401,MATCH(9,'Binder Setup'!$G$2:$G$401,0)))} -> 0.39 | F14: =IF(B14="","",IF(OR(D14>=$D$3,E14>=$E$3),"Pull","Skip: buy elsewhere")) -> Skip: buy elsewhere | G14: FALSE | J14: FALSE | K14: =IF(I14="","",COUNTIFS('Binder Data'!$Q$2:$Q$6251,I14,'Binder Data'!$D$2:$D$6251,"Needed"))
A15: =IF(B15="","",10) -> 10 | B15: {=IFERROR(INDEX('Binder Setup'!$B$2:$B$401,MATCH(10,'Binder Setup'!$G$2:$G$401,0)),"")} -> Aetherdrift Commander | C15: {=IF(B15="","",TEXTJOIN(", ",TRUE(),IF(('Binder Data'!$B$2:$B$6251=B15)*('Binder Data'!$E$2:$E$6251="Y"),'Binder Data'!$G$2:$G$6251,"")))} -> Retrofitter Foundry [Deck 1], Stridehangar Automaton [Deck 1] | D15: {=IF(B15="","",INDEX('Binder Setup'!$D$2:$D$401,MATCH(10,'Binder Setup'!$G$2:$G$401,0)))} -> 2 | E15: {=IF(B15="","",INDEX('Binder Setup'!$E$2:$E$401,MATCH(10,'Binder Setup'!$G$2:$G$401,0)))} -> 2.55 | F15: =IF(B15="","",IF(OR(D15>=$D$3,E15>=$E$3),"Pull","Skip: buy elsewhere")) -> Pull | G15: FALSE | J15: FALSE | K15: =IF(I15="","",COUNTIFS('Binder Data'!$Q$2:$Q$6251,I15,'Binder Data'!$D$2:$D$6251,"Needed"))
A16: =IF(B16="","",11) -> 11 | B16: {=IFERROR(INDEX('Binder Setup'!$B$2:$B$401,MATCH(11,'Binder Setup'!$G$2:$G$401,0)),"")} -> Foundations Commander | C16: {=IF(B16="","",TEXTJOIN(", ",TRUE(),IF(('Binder Data'!$B$2:$B$6251=B16)*('Binder Data'!$E$2:$E$6251="Y"),'Binder Data'!$G$2:$G$6251,"")))} -> Count on Luck [Deck 1] | D16: {=IF(B16="","",INDEX('Binder Setup'!$D$2:$D$401,MATCH(11,'Binder Setup'!$G$2:$G$401,0)))} -> 1 | E16: {=IF(B16="","",INDEX('Binder Setup'!$E$2:$E$401,MATCH(11,'Binder Setup'!$G$2:$G$401,0)))} -> 0.32 | F16: =IF(B16="","",IF(OR(D16>=$D$3,E16>=$E$3),"Pull","Skip: buy elsewhere")) -> Skip: buy elsewhere | G16: FALSE | J16: FALSE | K16: =IF(I16="","",COUNTIFS('Binder Data'!$Q$2:$Q$6251,I16,'Binder Data'!$D$2:$D$6251,"Needed"))
A17: =IF(B17="","",12) -> 12 | B17: {=IFERROR(INDEX('Binder Setup'!$B$2:$B$401,MATCH(12,'Binder Setup'!$G$2:$G$401,0)),"")} -> The Brothers' War Commander | C17: {=IF(B17="","",TEXTJOIN(", ",TRUE(),IF(('Binder Data'!$B$2:$B$6251=B17)*('Binder Data'!$E$2:$E$6251="Y"),'Binder Data'!$G$2:$G$6251,"")))} -> Thopter Shop [Deck 1] | D17: {=IF(B17="","",INDEX('Binder Setup'!$D$2:$D$401,MATCH(12,'Binder Setup'!$G$2:$G$401,0)))} -> 1 | E17: {=IF(B17="","",INDEX('Binder Setup'!$E$2:$E$401,MATCH(12,'Binder Setup'!$G$2:$G$401,0)))} -> 0.47 | F17: =IF(B17="","",IF(OR(D17>=$D$3,E17>=$E$3),"Pull","Skip: buy elsewhere")) -> Skip: buy elsewhere | G17: FALSE | J17: FALSE | K17: =IF(I17="","",COUNTIFS('Binder Data'!$Q$2:$Q$6251,I17,'Binder Data'!$D$2:$D$6251,"Needed"))
A18: =IF(B18="","",13) -> 13 | B18: {=IFERROR(INDEX('Binder Setup'!$B$2:$B$401,MATCH(13,'Binder Setup'!$G$2:$G$401,0)),"")} -> Commander Legends: Battle for Baldur's Gate | C18: {=IF(B18="","",TEXTJOIN(", ",TRUE(),IF(('Binder Data'!$B$2:$B$6251=B18)*('Binder Data'!$E$2:$E$6251="Y"),'Binder Data'!$G$2:$G$6251,"")))} -> Ingenious Artillerist [Deck 1] | D18: {=IF(B18="","",INDEX('Binder Setup'!$D$2:$D$401,MATCH(13,'Binder Setup'!$G$2:$G$401,0)))} -> 1 | E18: {=IF(B18="","",INDEX('Binder Setup'!$E$2:$E$401,MATCH(13,'Binder Setup'!$G$2:$G$401,0)))} -> 2.21 | F18: =IF(B18="","",IF(OR(D18>=$D$3,E18>=$E$3),"Pull","Skip: buy elsewhere")) -> Pull | G18: FALSE | J18: FALSE | K18: =IF(I18="","",COUNTIFS('Binder Data'!$Q$2:$Q$6251,I18,'Binder Data'!$D$2:$D$6251,"Needed"))
A19: =IF(B19="","",14) -> 14 | B19: {=IFERROR(INDEX('Binder Setup'!$B$2:$B$401,MATCH(14,'Binder Setup'!$G$2:$G$401,0)),"")} -> Doctor Who | C19: {=IF(B19="","",TEXTJOIN(", ",TRUE(),IF(('Binder Data'!$B$2:$B$6251=B19)*('Binder Data'!$E$2:$E$6251="Y"),'Binder Data'!$G$2:$G$6251,"")))} -> Sunbaked Canyon [Deck 1], Sundown Pass [Deck 1] | D19: {=IF(B19="","",INDEX('Binder Setup'!$D$2:$D$401,MATCH(14,'Binder Setup'!$G$2:$G$401,0)))} -> 2 | E19: {=IF(B19="","",INDEX('Binder Setup'!$E$2:$E$401,MATCH(14,'Binder Setup'!$G$2:$G$401,0)))} -> 7.45 | F19: =IF(B19="","",IF(OR(D19>=$D$3,E19>=$E$3),"Pull","Skip: buy elsewhere")) -> Pull | G19: FALSE | J19: FALSE | K19: =IF(I19="","",COUNTIFS('Binder Data'!$Q$2:$Q$6251,I19,'Binder Data'!$D$2:$D$6251,"Needed"))
A20: =IF(B20="","",15) -> 15 | B20: {=IFERROR(INDEX('Binder Setup'!$B$2:$B$401,MATCH(15,'Binder Setup'!$G$2:$G$401,0)),"")} -> Kaladesh | C20: {=IF(B20="","",TEXTJOIN(", ",TRUE(),IF(('Binder Data'!$B$2:$B$6251=B20)*('Binder Data'!$E$2:$E$6251="Y"),'Binder Data'!$G$2:$G$6251,"")))} -> Master Trinketeer [Deck 1] | D20: {=IF(B20="","",INDEX('Binder Setup'!$D$2:$D$401,MATCH(15,'Binder Setup'!$G$2:$G$401,0)))} -> 1 | E20: {=IF(B20="","",INDEX('Binder Setup'!$E$2:$E$401,MATCH(15,'Binder Setup'!$G$2:$G$401,0)))} -> 0.24 | F20: =IF(B20="","",IF(OR(D20>=$D$3,E20>=$E$3),"Pull","Skip: buy elsewhere")) -> Skip: buy elsewhere | G20: FALSE | J20: FALSE | K20: =IF(I20="","",COUNTIFS('Binder Data'!$Q$2:$Q$6251,I20,'Binder Data'!$D$2:$D$6251,"Needed"))
A21: =IF(B21="","",16) -> 16 | B21: {=IFERROR(INDEX('Binder Setup'!$B$2:$B$401,MATCH(16,'Binder Setup'!$G$2:$G$401,0)),"")} -> March of the Machine Commander | C21: {=IF(B21="","",TEXTJOIN(", ",TRUE(),IF(('Binder Data'!$B$2:$B$6251=B21)*('Binder Data'!$E$2:$E$6251="Y"),'Binder Data'!$G$2:$G$6251,"")))} -> Hedron Detonator [Deck 1] | D21: {=IF(B21="","",INDEX('Binder Setup'!$D$2:$D$401,MATCH(16,'Binder Setup'!$G$2:$G$401,0)))} -> 1 | E21: {=IF(B21="","",INDEX('Binder Setup'!$E$2:$E$401,MATCH(16,'Binder Setup'!$G$2:$G$401,0)))} -> 7.65 | F21: =IF(B21="","",IF(OR(D21>=$D$3,E21>=$E$3),"Pull","Skip: buy elsewhere")) -> Pull | G21: FALSE | J21: FALSE | K21: =IF(I21="","",COUNTIFS('Binder Data'!$Q$2:$Q$6251,I21,'Binder Data'!$D$2:$D$6251,"Needed"))
A22: =IF(B22="","",17) -> 17 | B22: {=IFERROR(INDEX('Binder Setup'!$B$2:$B$401,MATCH(17,'Binder Setup'!$G$2:$G$401,0)),"")} -> Modern Horizons 3 | C22: {=IF(B22="","",TEXTJOIN(", ",TRUE(),IF(('Binder Data'!$B$2:$B$6251=B22)*('Binder Data'!$E$2:$E$6251="Y"),'Binder Data'!$G$2:$G$6251,"")))} -> Molten Gatekeeper [Deck 1], Party Thrasher [Deck 1], Unstable Amulet [Deck 1] | D22: {=IF(B22="","",INDEX('Binder Setup'!$D$2:$D$401,MATCH(17,'Binder Setup'!$G$2:$G$401,0)))} -> 3 | E22: {=IF(B22="","",INDEX('Binder Setup'!$E$2:$E$401,MATCH(17,'Binder Setup'!$G$2:$G$401,0)))} -> 1.02 | F22: =IF(B22="","",IF(OR(D22>=$D$3,E22>=$E$3),"Pull","Skip: buy elsewhere")) -> Pull | G22: FALSE | J22: FALSE | K22: =IF(I22="","",COUNTIFS('Binder Data'!$Q$2:$Q$6251,I22,'Binder Data'!$D$2:$D$6251,"Needed"))
A23: =IF(B23="","",18) -> 18 | B23: {=IFERROR(INDEX('Binder Setup'!$B$2:$B$401,MATCH(18,'Binder Setup'!$G$2:$G$401,0)),"")} -> Duskmourn: House of Horror | C23: {=IF(B23="","",TEXTJOIN(", ",TRUE(),IF(('Binder Data'!$B$2:$B$6251=B23)*('Binder Data'!$E$2:$E$6251="Y"),'Binder Data'!$G$2:$G$6251,"")))} -> Dollmaker's Shop // Porcelain Gallery [Deck 1] | D23: {=IF(B23="","",INDEX('Binder Setup'!$D$2:$D$401,MATCH(18,'Binder Setup'!$G$2:$G$401,0)))} -> 1 | E23: {=IF(B23="","",INDEX('Binder Setup'!$E$2:$E$401,MATCH(18,'Binder Setup'!$G$2:$G$401,0)))} -> 5.99 | F23: =IF(B23="","",IF(OR(D23>=$D$3,E23>=$E$3),"Pull","Skip: buy elsewhere")) -> Pull | G23: FALSE | J23: FALSE | K23: =IF(I23="","",COUNTIFS('Binder Data'!$Q$2:$Q$6251,I23,'Binder Data'!$D$2:$D$6251,"Needed"))
A24: =IF(B24="","",19) -> 19 | B24: {=IFERROR(INDEX('Binder Setup'!$B$2:$B$401,MATCH(19,'Binder Setup'!$G$2:$G$401,0)),"")} -> Marvel's Spider-Man | C24: {=IF(B24="","",TEXTJOIN(", ",TRUE(),IF(('Binder Data'!$B$2:$B$6251=B24)*('Binder Data'!$E$2:$E$6251="Y"),'Binder Data'!$G$2:$G$6251,"")))} -> Interdimensional Web Watch [Deck 1], Shadow of the Goblin [Deck 1] | D24: {=IF(B24="","",INDEX('Binder Setup'!$D$2:$D$401,MATCH(19,'Binder Setup'!$G$2:$G$401,0)))} -> 2 | E24: {=IF(B24="","",INDEX('Binder Setup'!$E$2:$E$401,MATCH(19,'Binder Setup'!$G$2:$G$401,0)))} -> 1.03 | F24: =IF(B24="","",IF(OR(D24>=$D$3,E24>=$E$3),"Pull","Skip: buy elsewhere")) -> Pull | G24: FALSE | J24: FALSE | K24: =IF(I24="","",COUNTIFS('Binder Data'!$Q$2:$Q$6251,I24,'Binder Data'!$D$2:$D$6251,"Needed"))
A25: =IF(B25="","",20) -> 20 | B25: {=IFERROR(INDEX('Binder Setup'!$B$2:$B$401,MATCH(20,'Binder Setup'!$G$2:$G$401,0)),"")} -> Modern Horizons 2 | C25: {=IF(B25="","",TEXTJOIN(", ",TRUE(),IF(('Binder Data'!$B$2:$B$6251=B25)*('Binder Data'!$E$2:$E$6251="Y"),'Binder Data'!$G$2:$G$6251,"")))} -> Breya's Apprentice [Deck 1] | D25: {=IF(B25="","",INDEX('Binder Setup'!$D$2:$D$401,MATCH(20,'Binder Setup'!$G$2:$G$401,0)))} -> 1 | E25: {=IF(B25="","",INDEX('Binder Setup'!$E$2:$E$401,MATCH(20,'Binder Setup'!$G$2:$G$401,0)))} -> 0.36 | F25: =IF(B25="","",IF(OR(D25>=$D$3,E25>=$E$3),"Pull","Skip: buy elsewhere")) -> Skip: buy elsewhere | G25: FALSE | J25: FALSE | K25: =IF(I25="","",COUNTIFS('Binder Data'!$Q$2:$Q$6251,I25,'Binder Data'!$D$2:$D$6251,"Needed"))
A26: =IF(B26="","",21) -> 21 | B26: {=IFERROR(INDEX('Binder Setup'!$B$2:$B$401,MATCH(21,'Binder Setup'!$G$2:$G$401,0)),"")} -> Secrets of Strixhaven | C26: {=IF(B26="","",TEXTJOIN(", ",TRUE(),IF(('Binder Data'!$B$2:$B$6251=B26)*('Binder Data'!$E$2:$E$6251="Y"),'Binder Data'!$G$2:$G$6251,"")))} -> Improvisation Capstone [Deck 1] | D26: {=IF(B26="","",INDEX('Binder Setup'!$D$2:$D$401,MATCH(21,'Binder Setup'!$G$2:$G$401,0)))} -> 1 | E26: {=IF(B26="","",INDEX('Binder Setup'!$E$2:$E$401,MATCH(21,'Binder Setup'!$G$2:$G$401,0)))} -> 9.83 | F26: =IF(B26="","",IF(OR(D26>=$D$3,E26>=$E$3),"Pull","Skip: buy elsewhere")) -> Pull | G26: FALSE | J26: FALSE | K26: =IF(I26="","",COUNTIFS('Binder Data'!$Q$2:$Q$6251,I26,'Binder Data'!$D$2:$D$6251,"Needed"))
A27: =IF(B27="","",22) -> 22 | B27: {=IFERROR(INDEX('Binder Setup'!$B$2:$B$401,MATCH(22,'Binder Setup'!$G$2:$G$401,0)),"")} -> Streets of New Capenna | C27: {=IF(B27="","",TEXTJOIN(", ",TRUE(),IF(('Binder Data'!$B$2:$B$6251=B27)*('Binder Data'!$E$2:$E$6251="Y"),'Binder Data'!$G$2:$G$6251,"")))} -> Witty Roastmaster [Deck 1] | D27: {=IF(B27="","",INDEX('Binder Setup'!$D$2:$D$401,MATCH(22,'Binder Setup'!$G$2:$G$401,0)))} -> 1 | E27: {=IF(B27="","",INDEX('Binder Setup'!$E$2:$E$401,MATCH(22,'Binder Setup'!$G$2:$G$401,0)))} -> 0.93 | F27: =IF(B27="","",IF(OR(D27>=$D$3,E27>=$E$3),"Pull","Skip: buy elsewhere")) -> Skip: buy elsewhere | G27: FALSE | J27: FALSE | K27: =IF(I27="","",COUNTIFS('Binder Data'!$Q$2:$Q$6251,I27,'Binder Data'!$D$2:$D$6251,"Needed"))
A28: =IF(B28="","",23) -> 23 | B28: {=IFERROR(INDEX('Binder Setup'!$B$2:$B$401,MATCH(23,'Binder Setup'!$G$2:$G$401,0)),"")} -> The Lost Caverns of Ixalan | C28: {=IF(B28="","",TEXTJOIN(", ",TRUE(),IF(('Binder Data'!$B$2:$B$6251=B28)*('Binder Data'!$E$2:$E$6251="Y"),'Binder Data'!$G$2:$G$6251,"")))} -> Bonehoard Dracosaur [Deck 1] | D28: {=IF(B28="","",INDEX('Binder Setup'!$D$2:$D$401,MATCH(23,'Binder Setup'!$G$2:$G$401,0)))} -> 1 | E28: {=IF(B28="","",INDEX('Binder Setup'!$E$2:$E$401,MATCH(23,'Binder Setup'!$G$2:$G$401,0)))} -> 14.99 | F28: =IF(B28="","",IF(OR(D28>=$D$3,E28>=$E$3),"Pull","Skip: buy elsewhere")) -> Pull | G28: FALSE | J28: FALSE | K28: =IF(I28="","",COUNTIFS('Binder Data'!$Q$2:$Q$6251,I28,'Binder Data'!$D$2:$D$6251,"Needed"))
A29: =IF(B29="","",24) -> 24 | B29: {=IFERROR(INDEX('Binder Setup'!$B$2:$B$401,MATCH(24,'Binder Setup'!$G$2:$G$401,0)),"")} -> Edge of Eternities | C29: {=IF(B29="","",TEXTJOIN(", ",TRUE(),IF(('Binder Data'!$B$2:$B$6251=B29)*('Binder Data'!$E$2:$E$6251="Y"),'Binder Data'!$G$2:$G$6251,"")))} -> Weftstalker Ardent [Deck 1] | D29: {=IF(B29="","",INDEX('Binder Setup'!$D$2:$D$401,MATCH(24,'Binder Setup'!$G$2:$G$401,0)))} -> 1 | E29: {=IF(B29="","",INDEX('Binder Setup'!$E$2:$E$401,MATCH(24,'Binder Setup'!$G$2:$G$401,0)))} -> 2.69 | F29: =IF(B29="","",IF(OR(D29>=$D$3,E29>=$E$3),"Pull","Skip: buy elsewhere")) -> Pull | G29: FALSE | J29: FALSE | K29: =IF(I29="","",COUNTIFS('Binder Data'!$Q$2:$Q$6251,I29,'Binder Data'!$D$2:$D$6251,"Needed"))
A30: =IF(B30="","",25) -> 25 | B30: {=IFERROR(INDEX('Binder Setup'!$B$2:$B$401,MATCH(25,'Binder Setup'!$G$2:$G$401,0)),"")} -> March of the Machine | C30: {=IF(B30="","",TEXTJOIN(", ",TRUE(),IF(('Binder Data'!$B$2:$B$6251=B30)*('Binder Data'!$E$2:$E$6251="Y"),'Binder Data'!$G$2:$G$6251,"")))} -> Invasion of Kaldheim // Pyre of the World Tree [Deck 1] | D30: {=IF(B30="","",INDEX('Binder Setup'!$D$2:$D$401,MATCH(25,'Binder Setup'!$G$2:$G$401,0)))} -> 1 | E30: {=IF(B30="","",INDEX('Binder Setup'!$E$2:$E$401,MATCH(25,'Binder Setup'!$G$2:$G$401,0)))} -> 0.39 | F30: =IF(B30="","",IF(OR(D30>=$D$3,E30>=$E$3),"Pull","Skip: buy elsewhere")) -> Skip: buy elsewhere | G30: FALSE | J30: FALSE | K30: =IF(I30="","",COUNTIFS('Binder Data'!$Q$2:$Q$6251,I30,'Binder Data'!$D$2:$D$6251,"Needed"))
A31: =IF(B31="","",26) -> 26 | B31: {=IFERROR(INDEX('Binder Setup'!$B$2:$B$401,MATCH(26,'Binder Setup'!$G$2:$G$401,0)),"")} -> March of the Machine: The Aftermath | C31: {=IF(B31="","",TEXTJOIN(", ",TRUE(),IF(('Binder Data'!$B$2:$B$6251=B31)*('Binder Data'!$E$2:$E$6251="Y"),'Binder Data'!$G$2:$G$6251,"")))} -> Pia Nalaar, Consul of Revival [Deck 1] | D31: {=IF(B31="","",INDEX('Binder Setup'!$D$2:$D$401,MATCH(26,'Binder Setup'!$G$2:$G$401,0)))} -> 1 | E31: {=IF(B31="","",INDEX('Binder Setup'!$E$2:$E$401,MATCH(26,'Binder Setup'!$G$2:$G$401,0)))} -> 0.52 | F31: =IF(B31="","",IF(OR(D31>=$D$3,E31>=$E$3),"Pull","Skip: buy elsewhere")) -> Skip: buy elsewhere | G31: FALSE
A32: =IF(B32="","",27) -> 27 | B32: {=IFERROR(INDEX('Binder Setup'!$B$2:$B$401,MATCH(27,'Binder Setup'!$G$2:$G$401,0)),"")} -> Tarkir: Dragonstorm | C32: {=IF(B32="","",TEXTJOIN(", ",TRUE(),IF(('Binder Data'!$B$2:$B$6251=B32)*('Binder Data'!$E$2:$E$6251="Y"),'Binder Data'!$G$2:$G$6251,"")))} -> Cori Mountain Monastery [Deck 1] | D32: {=IF(B32="","",INDEX('Binder Setup'!$D$2:$D$401,MATCH(27,'Binder Setup'!$G$2:$G$401,0)))} -> 1 | E32: {=IF(B32="","",INDEX('Binder Setup'!$E$2:$E$401,MATCH(27,'Binder Setup'!$G$2:$G$401,0)))} -> 1.16 | F32: =IF(B32="","",IF(OR(D32>=$D$3,E32>=$E$3),"Pull","Skip: buy elsewhere")) -> Pull | G32: FALSE | I32: Every tab with "In Collection?" in A1 is a list, in tab order, up to 25. Added, renamed or moved a list tab? Reload the sheet or run Card Finder > Refresh lists. Ticks stay with their list.
A33: =IF(B33="","",28) -> 28 | B33: {=IFERROR(INDEX('Binder Setup'!$B$2:$B$401,MATCH(28,'Binder Setup'!$G$2:$G$401,0)),"")} -> The Hobbit | C33: {=IF(B33="","",TEXTJOIN(", ",TRUE(),IF(('Binder Data'!$B$2:$B$6251=B33)*('Binder Data'!$E$2:$E$6251="Y"),'Binder Data'!$G$2:$G$6251,"")))} -> Belladonna Took [Deck 1] | D33: {=IF(B33="","",INDEX('Binder Setup'!$D$2:$D$401,MATCH(28,'Binder Setup'!$G$2:$G$401,0)))} -> 1 | E33: {=IF(B33="","",INDEX('Binder Setup'!$E$2:$E$401,MATCH(28,'Binder Setup'!$G$2:$G$401,0)))} -> 2.43 | F33: =IF(B33="","",IF(OR(D33>=$D$3,E33>=$E$3),"Pull","Skip: buy elsewhere")) -> Pull | G33: FALSE
A34: =IF(B34="","",29) | B34: {=IFERROR(INDEX('Binder Setup'!$B$2:$B$401,MATCH(29,'Binder Setup'!$G$2:$G$401,0)),"")} | C34: {=IF(B34="","",TEXTJOIN(", ",TRUE(),IF(('Binder Data'!$B$2:$B$6251=B34)*('Binder Data'!$E$2:$E$6251="Y"),'Binder Data'!$G$2:$G$6251,"")))} | D34: {=IF(B34="","",INDEX('Binder Setup'!$D$2:$D$401,MATCH(29,'Binder Setup'!$G$2:$G$401,0)))} | E34: {=IF(B34="","",INDEX('Binder Setup'!$E$2:$E$401,MATCH(29,'Binder Setup'!$G$2:$G$401,0)))} | F34: =IF(B34="","",IF(OR(D34>=$D$3,E34>=$E$3),"Pull","Skip: buy elsewhere")) | G34: FALSE
A35: =IF(B35="","",30) | B35: {=IFERROR(INDEX('Binder Setup'!$B$2:$B$401,MATCH(30,'Binder Setup'!$G$2:$G$401,0)),"")} | C35: {=IF(B35="","",TEXTJOIN(", ",TRUE(),IF(('Binder Data'!$B$2:$B$6251=B35)*('Binder Data'!$E$2:$E$6251="Y"),'Binder Data'!$G$2:$G$6251,"")))} | D35: {=IF(B35="","",INDEX('Binder Setup'!$D$2:$D$401,MATCH(30,'Binder Setup'!$G$2:$G$401,0)))} | E35: {=IF(B35="","",INDEX('Binder Setup'!$E$2:$E$401,MATCH(30,'Binder Setup'!$G$2:$G$401,0)))} | F35: =IF(B35="","",IF(OR(D35>=$D$3,E35>=$E$3),"Pull","Skip: buy elsewhere")) | G35: FALSE
A36: =IF(B36="","",31) | B36: {=IFERROR(INDEX('Binder Setup'!$B$2:$B$401,MATCH(31,'Binder Setup'!$G$2:$G$401,0)),"")} | C36: {=IF(B36="","",TEXTJOIN(", ",TRUE(),IF(('Binder Data'!$B$2:$B$6251=B36)*('Binder Data'!$E$2:$E$6251="Y"),'Binder Data'!$G$2:$G$6251,"")))} | D36: {=IF(B36="","",INDEX('Binder Setup'!$D$2:$D$401,MATCH(31,'Binder Setup'!$G$2:$G$401,0)))} | E36: {=IF(B36="","",INDEX('Binder Setup'!$E$2:$E$401,MATCH(31,'Binder Setup'!$G$2:$G$401,0)))} | F36: =IF(B36="","",IF(OR(D36>=$D$3,E36>=$E$3),"Pull","Skip: buy elsewhere")) | G36: FALSE
A37: =IF(B37="","",32) | B37: {=IFERROR(INDEX('Binder Setup'!$B$2:$B$401,MATCH(32,'Binder Setup'!$G$2:$G$401,0)),"")} | C37: {=IF(B37="","",TEXTJOIN(", ",TRUE(),IF(('Binder Data'!$B$2:$B$6251=B37)*('Binder Data'!$E$2:$E$6251="Y"),'Binder Data'!$G$2:$G$6251,"")))} | D37: {=IF(B37="","",INDEX('Binder Setup'!$D$2:$D$401,MATCH(32,'Binder Setup'!$G$2:$G$401,0)))} | E37: {=IF(B37="","",INDEX('Binder Setup'!$E$2:$E$401,MATCH(32,'Binder Setup'!$G$2:$G$401,0)))} | F37: =IF(B37="","",IF(OR(D37>=$D$3,E37>=$E$3),"Pull","Skip: buy elsewhere")) | G37: FALSE
A38: =IF(B38="","",33) | B38: {=IFERROR(INDEX('Binder Setup'!$B$2:$B$401,MATCH(33,'Binder Setup'!$G$2:$G$401,0)),"")} | C38: {=IF(B38="","",TEXTJOIN(", ",TRUE(),IF(('Binder Data'!$B$2:$B$6251=B38)*('Binder Data'!$E$2:$E$6251="Y"),'Binder Data'!$G$2:$G$6251,"")))} | D38: {=IF(B38="","",INDEX('Binder Setup'!$D$2:$D$401,MATCH(33,'Binder Setup'!$G$2:$G$401,0)))} | E38: {=IF(B38="","",INDEX('Binder Setup'!$E$2:$E$401,MATCH(33,'Binder Setup'!$G$2:$G$401,0)))} | F38: =IF(B38="","",IF(OR(D38>=$D$3,E38>=$E$3),"Pull","Skip: buy elsewhere")) | G38: FALSE
A39: =IF(B39="","",34) | B39: {=IFERROR(INDEX('Binder Setup'!$B$2:$B$401,MATCH(34,'Binder Setup'!$G$2:$G$401,0)),"")} | C39: {=IF(B39="","",TEXTJOIN(", ",TRUE(),IF(('Binder Data'!$B$2:$B$6251=B39)*('Binder Data'!$E$2:$E$6251="Y"),'Binder Data'!$G$2:$G$6251,"")))} | D39: {=IF(B39="","",INDEX('Binder Setup'!$D$2:$D$401,MATCH(34,'Binder Setup'!$G$2:$G$401,0)))} | E39: {=IF(B39="","",INDEX('Binder Setup'!$E$2:$E$401,MATCH(34,'Binder Setup'!$G$2:$G$401,0)))} | F39: =IF(B39="","",IF(OR(D39>=$D$3,E39>=$E$3),"Pull","Skip: buy elsewhere")) | G39: FALSE
A40: =IF(B40="","",35) | B40: {=IFERROR(INDEX('Binder Setup'!$B$2:$B$401,MATCH(35,'Binder Setup'!$G$2:$G$401,0)),"")} | C40: {=IF(B40="","",TEXTJOIN(", ",TRUE(),IF(('Binder Data'!$B$2:$B$6251=B40)*('Binder Data'!$E$2:$E$6251="Y"),'Binder Data'!$G$2:$G$6251,"")))} | D40: {=IF(B40="","",INDEX('Binder Setup'!$D$2:$D$401,MATCH(35,'Binder Setup'!$G$2:$G$401,0)))} | E40: {=IF(B40="","",INDEX('Binder Setup'!$E$2:$E$401,MATCH(35,'Binder Setup'!$G$2:$G$401,0)))} | F40: =IF(B40="","",IF(OR(D40>=$D$3,E40>=$E$3),"Pull","Skip: buy elsewhere")) | G40: FALSE
...

Sheet Wishlist
A1: In Collection? | B1: count | C1: name | D1: type_line | E1: mana_cost | F1: target_binder | G1: set_name | H1: cmc | I1: rarity | J1: price_usd | K1: colors | L1: oracle_text | M1: scryfall_uri | N1: set_prices | O1: image_uri
A2: FALSE | F2: {=IF(INDEX('Binder Data'!$A$2:$A$251,ROW()-1)="","",IF(INDEX('Binder Data'!$D$2:$D$251,ROW()-1)="Needed",INDEX('Binder Data'!$B$2:$B$251,ROW()-1),INDEX('Binder Data'!$D$2:$D$251,ROW()-1)))}
A3: FALSE | F3: {=IF(INDEX('Binder Data'!$A$2:$A$251,ROW()-1)="","",IF(INDEX('Binder Data'!$D$2:$D$251,ROW()-1)="Needed",INDEX('Binder Data'!$B$2:$B$251,ROW()-1),INDEX('Binder Data'!$D$2:$D$251,ROW()-1)))}
A4: FALSE | F4: {=IF(INDEX('Binder Data'!$A$2:$A$251,ROW()-1)="","",IF(INDEX('Binder Data'!$D$2:$D$251,ROW()-1)="Needed",INDEX('Binder Data'!$B$2:$B$251,ROW()-1),INDEX('Binder Data'!$D$2:$D$251,ROW()-1)))}
A5: FALSE | F5: {=IF(INDEX('Binder Data'!$A$2:$A$251,ROW()-1)="","",IF(INDEX('Binder Data'!$D$2:$D$251,ROW()-1)="Needed",INDEX('Binder Data'!$B$2:$B$251,ROW()-1),INDEX('Binder Data'!$D$2:$D$251,ROW()-1)))}
A6: FALSE | F6: {=IF(INDEX('Binder Data'!$A$2:$A$251,ROW()-1)="","",IF(INDEX('Binder Data'!$D$2:$D$251,ROW()-1)="Needed",INDEX('Binder Data'!$B$2:$B$251,ROW()-1),INDEX('Binder Data'!$D$2:$D$251,ROW()-1)))}
A7: FALSE | F7: {=IF(INDEX('Binder Data'!$A$2:$A$251,ROW()-1)="","",IF(INDEX('Binder Data'!$D$2:$D$251,ROW()-1)="Needed",INDEX('Binder Data'!$B$2:$B$251,ROW()-1),INDEX('Binder Data'!$D$2:$D$251,ROW()-1)))}
A8: FALSE | F8: {=IF(INDEX('Binder Data'!$A$2:$A$251,ROW()-1)="","",IF(INDEX('Binder Data'!$D$2:$D$251,ROW()-1)="Needed",INDEX('Binder Data'!$B$2:$B$251,ROW()-1),INDEX('Binder Data'!$D$2:$D$251,ROW()-1)))}
A9: FALSE | F9: {=IF(INDEX('Binder Data'!$A$2:$A$251,ROW()-1)="","",IF(INDEX('Binder Data'!$D$2:$D$251,ROW()-1)="Needed",INDEX('Binder Data'!$B$2:$B$251,ROW()-1),INDEX('Binder Data'!$D$2:$D$251,ROW()-1)))}
A10: FALSE | F10: {=IF(INDEX('Binder Data'!$A$2:$A$251,ROW()-1)="","",IF(INDEX('Binder Data'!$D$2:$D$251,ROW()-1)="Needed",INDEX('Binder Data'!$B$2:$B$251,ROW()-1),INDEX('Binder Data'!$D$2:$D$251,ROW()-1)))}
A11: FALSE | F11: {=IF(INDEX('Binder Data'!$A$2:$A$251,ROW()-1)="","",IF(INDEX('Binder Data'!$D$2:$D$251,ROW()-1)="Needed",INDEX('Binder Data'!$B$2:$B$251,ROW()-1),INDEX('Binder Data'!$D$2:$D$251,ROW()-1)))}
A12: FALSE | F12: {=IF(INDEX('Binder Data'!$A$2:$A$251,ROW()-1)="","",IF(INDEX('Binder Data'!$D$2:$D$251,ROW()-1)="Needed",INDEX('Binder Data'!$B$2:$B$251,ROW()-1),INDEX('Binder Data'!$D$2:$D$251,ROW()-1)))}
A13: FALSE | F13: {=IF(INDEX('Binder Data'!$A$2:$A$251,ROW()-1)="","",IF(INDEX('Binder Data'!$D$2:$D$251,ROW()-1)="Needed",INDEX('Binder Data'!$B$2:$B$251,ROW()-1),INDEX('Binder Data'!$D$2:$D$251,ROW()-1)))}
... A89: FALSE | F89: {=IF(INDEX('Binder Data'!$A$2:$A$251,ROW()-1)="","",IF(INDEX('Binder Data'!$D$2:$D$251,ROW()-1)="Needed",INDEX('Binder Data'!$B$2:$B$251,ROW()-1),INDEX('Binder Data'!$D$2:$D$251,ROW()-1)))}
F90: {=IF(INDEX('Binder Data'!$A$2:$A$251,ROW()-1)="","",IF(INDEX('Binder Data'!$D$2:$D$251,ROW()-1)="Needed",INDEX('Binder Data'!$B$2:$B$251,ROW()-1),INDEX('Binder Data'!$D$2:$D$251,ROW()-1)))}
F91: {=IF(INDEX('Binder Data'!$A$2:$A$251,ROW()-1)="","",IF(INDEX('Binder Data'!$D$2:$D$251,ROW()-1)="Needed",INDEX('Binder Data'!$B$2:$B$251,ROW()-1),INDEX('Binder Data'!$D$2:$D$251,ROW()-1)))}
F92: {=IF(INDEX('Binder Data'!$A$2:$A$251,ROW()-1)="","",IF(INDEX('Binder Data'!$D$2:$D$251,ROW()-1)="Needed",INDEX('Binder Data'!$B$2:$B$251,ROW()-1),INDEX('Binder Data'!$D$2:$D$251,ROW()-1)))}
F93: {=IF(INDEX('Binder Data'!$A$2:$A$251,ROW()-1)="","",IF(INDEX('Binder Data'!$D$2:$D$251,ROW()-1)="Needed",INDEX('Binder Data'!$B$2:$B$251,ROW()-1),INDEX('Binder Data'!$D$2:$D$251,ROW()-1)))}
F94: {=IF(INDEX('Binder Data'!$A$2:$A$251,ROW()-1)="","",IF(INDEX('Binder Data'!$D$2:$D$251,ROW()-1)="Needed",INDEX('Binder Data'!$B$2:$B$251,ROW()-1),INDEX('Binder Data'!$D$2:$D$251,ROW()-1)))}
F95: {=IF(INDEX('Binder Data'!$A$2:$A$251,ROW()-1)="","",IF(INDEX('Binder Data'!$D$2:$D$251,ROW()-1)="Needed",INDEX('Binder Data'!$B$2:$B$251,ROW()-1),INDEX('Binder Data'!$D$2:$D$251,ROW()-1)))}
F96: {=IF(INDEX('Binder Data'!$A$2:$A$251,ROW()-1)="","",IF(INDEX('Binder Data'!$D$2:$D$251,ROW()-1)="Needed",INDEX('Binder Data'!$B$2:$B$251,ROW()-1),INDEX('Binder Data'!$D$2:$D$251,ROW()-1)))}
F97: {=IF(INDEX('Binder Data'!$A$2:$A$251,ROW()-1)="","",IF(INDEX('Binder Data'!$D$2:$D$251,ROW()-1)="Needed",INDEX('Binder Data'!$B$2:$B$251,ROW()-1),INDEX('Binder Data'!$D$2:$D$251,ROW()-1)))}
F98: {=IF(INDEX('Binder Data'!$A$2:$A$251,ROW()-1)="","",IF(INDEX('Binder Data'!$D$2:$D$251,ROW()-1)="Needed",INDEX('Binder Data'!$B$2:$B$251,ROW()-1),INDEX('Binder Data'!$D$2:$D$251,ROW()-1)))}
F99: {=IF(INDEX('Binder Data'!$A$2:$A$251,ROW()-1)="","",IF(INDEX('Binder Data'!$D$2:$D$251,ROW()-1)="Needed",INDEX('Binder Data'!$B$2:$B$251,ROW()-1),INDEX('Binder Data'!$D$2:$D$251,ROW()-1)))}
F100: {=IF(INDEX('Binder Data'!$A$2:$A$251,ROW()-1)="","",IF(INDEX('Binder Data'!$D$2:$D$251,ROW()-1)="Needed",INDEX('Binder Data'!$B$2:$B$251,ROW()-1),INDEX('Binder Data'!$D$2:$D$251,ROW()-1)))}
F101: {=IF(INDEX('Binder Data'!$A$2:$A$251,ROW()-1)="","",IF(INDEX('Binder Data'!$D$2:$D$251,ROW()-1)="Needed",INDEX('Binder Data'!$B$2:$B$251,ROW()-1),INDEX('Binder Data'!$D$2:$D$251,ROW()-1)))}
... F251: {=IF(INDEX('Binder Data'!$A$2:$A$251,ROW()-1)="","",IF(INDEX('Binder Data'!$D$2:$D$251,ROW()-1)="Needed",INDEX('Binder Data'!$B$2:$B$251,ROW()-1),INDEX('Binder Data'!$D$2:$D$251,ROW()-1)))}

Sheet Deck 1
A1: In Collection? | B1: count | C1: name | D1: type_line | E1: mana_cost | F1: target_binder | G1: set_name | H1: cmc | I1: rarity | J1: price_usd | K1: colors | L1: oracle_text | M1: scryfall_uri | N1: set_prices | O1: image_uri
A2: FALSE | B2: 1 | C2: Anim Pakal, Thousandth Moon | D2: Legendary Creature — Human Soldier | E2: {1}{R}{W} | F2: {=IF(INDEX('Binder Data'!$A$252:$A$501,ROW()-1)="","",IF(INDEX('Binder Data'!$D$252:$D$501,ROW()-1)="Needed",INDEX('Binder Data'!$B$252:$B$501,ROW()-1),INDEX('Binder Data'!$D$252:$D$501,ROW()-1)))} -> Foundations | G2: The List The Lost Caverns of Ixalan Promos The Lost Caverns of Ixalan | H2: 3 | I2: rare | J2: 4.07 | K2: RW | L2: Whenever you attack with one or more non-Gnome creatures, put a +1/+1 counter on Anim Pakal, then create X 1/1 colorless Gnome artifact creature tokens that are tapped and attacking, where X is the number of +1/+1 counters on Anim Pakal. | M2: https://scryfall.com/card/lci/223/anim-pakal-thousandth-moon?utm_source=api | N2: 6.49 4.07 | O2: https://cards.scryfall.io/small/front/8/6/868856b7-8875-43c1-8249-0f8fb2c8319b.jpg?1783913734
A3: FALSE | B3: 1 | C3: Arabella, Abandoned Doll | D3: Legendary Artifact Creature — Toy | E3: {R}{W} | F3: {=IF(INDEX('Binder Data'!$A$252:$A$501,ROW()-1)="","",IF(INDEX('Binder Data'!$D$252:$D$501,ROW()-1)="Needed",INDEX('Binder Data'!$B$252:$B$501,ROW()-1),INDEX('Binder Data'!$D$252:$D$501,ROW()-1)))} -> Foundations | G3: The List Duskmourn: House of Horror | H3: 2 | I3: uncommon | J3: 0.77 | K3: RW | L3: Whenever Arabella attacks, it deals X damage to each opponent and you gain X life, where X is the number of creatures you control with power 2 or less. | M3: https://scryfall.com/card/dsk/208/arabella-abandoned-doll?utm_source=api | N3: 0.77 | O3: https://cards.scryfall.io/small/front/f/6/f683d5a1-b8bf-446f-9fe3-88a4398bf3cf.jpg?1783909446
A4: FALSE | B4: 1 | C4: Battlefield Forge | D4: Land | F4: {=IF(INDEX('Binder Data'!$A$252:$A$501,ROW()-1)="","",IF(INDEX('Binder Data'!$D$252:$D$501,ROW()-1)="Needed",INDEX('Binder Data'!$B$252:$B$501,ROW()-1),INDEX('Binder Data'!$D$252:$D$501,ROW()-1)))} -> Secret Lair Drop | G4: Reality Fracture Commander Secrets of Strixhaven Commander Edge of Eternities Commander Final Fantasy Commander Tarkir: Dragonstorm Commander Bloomburrow Commander Modern Horizons 3 Commander Outlaws of Thunder Junction Commander Tales of Middle-earth Commander The Brothers' War Promos The Brothers' War Dominaria United Commander Secret Lair Drop Commander 2021 Commander 2020 Magic Origins Magic 2015 Tenth Edition Ninth Edition Apocalypse | H4: 0 | I4: rare | J4: 0.22 | L4: {T}: Add {C}. {T}: Add {R} or {W}. This land deals 1 damage to you. | M4: https://scryfall.com/card/frc/65/battlefield-forge?utm_source=api | N4: 0.22 0.35 0.32 0.30 0.34 0.34 0.35 0.39 0.45 0.95 0.37 0.36 56.76 0.43 0.36 0.35 0.45 3.07 3.62 10.60 | O4: https://cards.scryfall.io/small/front/e/f/ef7d3676-b1db-4329-9201-18f8a6c54ea6.jpg?1789599856
A5: FALSE | B5: 1 | C5: Belladonna Took | D5: Legendary Creature — Halfling Citizen | E5: {1}{W} | F5: {=IF(INDEX('Binder Data'!$A$252:$A$501,ROW()-1)="","",IF(INDEX('Binder Data'!$D$252:$D$501,ROW()-1)="Needed",INDEX('Binder Data'!$B$252:$B$501,ROW()-1),INDEX('Binder Data'!$D$252:$D$501,ROW()-1)))} -> The Hobbit | G5: The Hobbit | H5: 2 | I5: rare | J5: 2.43 | K5: W | L5: Whenever a token you control enters, you gain 1 life if this is the first time this ability has resolved this turn. If it's the second time, draw a card. If it's the third time, put a +1/+1 counter on each creature you control. | M5: https://scryfall.com/card/hob/4/belladonna-took?utm_source=api | N5: 2.43 | O5: https://cards.scryfall.io/small/front/8/8/88f0c189-c9ed-4ea3-ae62-3d8ac6c7fecf.jpg?1784894804
A6: FALSE | B6: 1 | C6: Blasphemous Act | D6: Sorcery | E6: {8}{R} | F6: {=IF(INDEX('Binder Data'!$A$252:$A$501,ROW()-1)="","",IF(INDEX('Binder Data'!$D$252:$D$501,ROW()-1)="Needed",INDEX('Binder Data'!$B$252:$B$501,ROW()-1),INDEX('Binder Data'!$D$252:$D$501,ROW()-1)))} -> Foundations | G6: Foundations Commander Marvel Super Heroes Commander The List Secrets of Strixhaven Commander Teenage Mutant Ninja Turtles Eternal Lorwyn Eclipsed Commander Avatar: The Last Airbender Eternal Secret Lair Drop Edge of Eternities Commander Tarkir: Dragonstorm Commander Aetherdrift Commander Duskmourn: House of Horror Commander Bloomburrow Commander Fallout The Lost Caverns of Ixalan Commander Doctor Who Commander Masters Tales of Middle-earth Commander Starter Commander Decks The Brothers' War Commander Warhammer 40,000 Commander Commander Legends: Battle for Baldur's Gate New Capenna Commander Crimson Vow Commander Commander 2021 Commander Legends Double Masters Commander 2018 Commander Anthology Volume II Commander 2016 Commander 2014 Innistrad | H6: 9 | I6: rare | J6: 0.76 | K6: R | L6: This spell costs {1} less to cast for each creature on the battlefield. Blasphemous Act deals 13 damage to each creature. | M6: https://scryfall.com/card/msc/163/blasphemous-act?utm_source=api | N6: 0.76 0.86 1.22 0.94 0.89 0.94 4.12 3.46 0.96 1.19 0.90 1.07 1.16 0.97 1.03 1.13 1.23 2.28 0.96 2.15 2.79 1.47 1.74 1.05 1.40 1.23 2.10 1.04 2.22 2.11 1.10 1.37 | O6: https://cards.scryfall.io/small/front/7/d/7d4b1d44-126e-4987-9a9f-f0f9627a09cb.jpg?1783903234
A7: FALSE | B7: 1 | C7: Bonehoard Dracosaur | D7: Creature — Dinosaur Dragon | E7: {3}{R}{R} | F7: {=IF(INDEX('Binder Data'!$A$252:$A$501,ROW()-1)="","",IF(INDEX('Binder Data'!$D$252:$D$501,ROW()-1)="Needed",INDEX('Binder Data'!$B$252:$B$501,ROW()-1),INDEX('Binder Data'!$D$252:$D$501,ROW()-1)))} -> The Lost Caverns of Ixalan | G7: The Lost Caverns of Ixalan Promos The Lost Caverns of Ixalan | H7: 5 | I7: mythic | J7: 14.99 | K7: R | L7: Flying, first strike At the beginning of your upkeep, exile the top two cards of your library. You may play them this turn. If you exiled a land card this way, create a 3/1 red Dinosaur creature token. If you exiled a nonland card this way, create a Treasure token. | M7: https://scryfall.com/card/lci/134/bonehoard-dracosaur?utm_source=api | N7: 20.04 14.99 | O7: https://cards.scryfall.io/small/front/2/2/2220ed60-3f8f-4dd2-8319-6a06896a5350.jpg?1783913768
A8: FALSE | B8: 1 | C8: Boros Signet | D8: Artifact | E8: {2} | F8: {=IF(INDEX('Binder Data'!$A$252:$A$501,ROW()-1)="","",IF(INDEX('Binder Data'!$D$252:$D$501,ROW()-1)="Needed",INDEX('Binder Data'!$B$252:$B$501,ROW()-1),INDEX('Binder Data'!$D$252:$D$501,ROW()-1)))} -> Secret Lair Drop | G8: Tarkir: Dragonstorm Commander Bloomburrow Commander Ravnica: Clue Edition Ravnica Remastered Commander Masters Phyrexia: All Will Be One Commander Secret Lair Drop Commander Legends Commander 2020 GRN Guild Kit Commander Anthology Volume II Commander 2017 Commander Anthology Modern Masters 2017 Commander 2015 Commander 2011 Planechase Ravnica: City of Guilds | H8: 2 | I8: uncommon | J8: 0.54 | L8: {1}, {T}: Add {R}{W}. | M8: https://scryfall.com/card/tdc/314/boros-signet?utm_source=api | N8: 0.66 0.62 0.63 1.55 1.70 1.93 15.79 0.56 2.14 0.67 0.65 0.62 0.90 0.58 0.54 0.76 1.11 1.84 | O8: https://cards.scryfall.io/small/front/4/9/49c37c0e-d363-4033-a069-710241cd9923.jpg?1783907016
A9: FALSE | B9: 1 | C9: Breya's Apprentice | D9: Artifact Creature — Human Artificer | E9: {2}{R} | F9: {=IF(INDEX('Binder Data'!$A$252:$A$501,ROW()-1)="","",IF(INDEX('Binder Data'!$D$252:$D$501,ROW()-1)="Needed",INDEX('Binder Data'!$B$252:$B$501,ROW()-1),INDEX('Binder Data'!$D$252:$D$501,ROW()-1)))} -> Modern Horizons 2 | G9: Modern Horizons 2 Modern Horizons 2 Promos | H9: 3 | I9: rare | J9: 0.36 | K9: R | L9: When this creature enters, create a 1/1 colorless Thopter artifact creature token with flying. {T}, Sacrifice an artifact: Choose one — • Exile the top card of your library. Until the end of your next turn, you may play that card. • Target creature gets +2/+0 until end of turn. | M9: https://scryfall.com/card/mh2/117/breyas-apprentice?utm_source=api | N9: 0.36 1.00 | O9: https://cards.scryfall.io/small/front/c/3/c32b5b2e-dabf-4672-b476-4873781f636e.jpg?1783926848
